<?xml version="1.0" ?>
<!-- =================================================================================== -->
<!-- |    This document was autogenerated by xacro from jey.urdf.xacro                 | -->
<!-- |    EDITING THIS FILE BY HAND IS NOT RECOMMENDED                                 | -->
<!-- =================================================================================== -->
<robot name="jey">
  <material name="black">
    <color rgba="0.0 0.0 0.0 1.0"/>
  </material>
  <material name="blue">
    <color rgba="0.0 0.0 0.8 1.0"/>
  </material>
  <material name="green">
    <color rgba="0.0 0.8 0.0 1.0"/>
  </material>
  <material name="grey">
    <color rgba="0.2 0.2 0.2 1.0"/>
  </material>
  <material name="silver">
    <color rgba="0.9137254901960784 0.9137254901960784 0.8470588235294118 1.0"/>
  </material>
  <material name="orange">
    <color rgba="1.0 0.4235294117647059 0.0392156862745098 1.0"/>
  </material>
  <material name="brown">
    <color rgba="0.8705882352941177 0.8117647058823529 0.7647058823529411 1.0"/>
  </material>
  <material name="red">
    <color rgba="0.8 0.0 0.0 1.0"/>
  </material>
  <material name="white">
    <color rgba="1.0 1.0 1.0 1.0"/>
  </material>
  <!-- ros_control plugin -->
  <gazebo>
    <plugin filename="libgazebo_ros_control.so" name="gazebo_ros_control">
      <robotNamespace>/jey_gazebo</robotNamespace>
      <robotSimType>gazebo_ros_control/DefaultRobotHWSim</robotSimType>
    </plugin>
  </gazebo>
  <!-- Show the trajectory of trunk center. -->
  <gazebo>
    <plugin filename="libLinkPlot3DPlugin.so" name="3dplot">
      <frequency>10</frequency>
      <plot>
        <link>base_link</link>
        <pose>0 0 0 0 0 0</pose>
        <material>Gazebo/Yellow</material>
      </plot>
    </plugin>
  </gazebo>
  <gazebo>
    <plugin filename="libgazebo_ros_force.so" name="gazebo_ros_force">
      <bodyName>trunk</bodyName>
      <topicName>/apply_force/trunk</topicName>
    </plugin>
  </gazebo>
  <gazebo reference="imu_link">
    <gravity>true</gravity>
    <sensor name="imu_sensor" type="imu">
      <always_on>true</always_on>
      <update_rate>1000</update_rate>
      <visualize>true</visualize>
      <topic>__default_topic__</topic>
      <plugin filename="libgazebo_ros_imu_sensor.so" name="imu_plugin">
        <topicName>trunk_imu</topicName>
        <bodyName>imu_link</bodyName>
        <updateRateHZ>1000.0</updateRateHZ>
        <gaussianNoise>0.0</gaussianNoise>
        <xyzOffset>0 0 0</xyzOffset>
        <rpyOffset>0 0 0</rpyOffset>
        <frameName>imu_link</frameName>
      </plugin>
      <pose>0 0 0 0 0 0</pose>
    </sensor>
  </gazebo>
  <gazebo reference="base_link">
    <material>Gazebo/Green</material>
    <turnGravityOff>false</turnGravityOff>
  </gazebo>
  <gazebo reference="trunk">
    <mu1>1.5</mu1>
    <mu2>1.5</mu2>
    <kp value="1000000.0"/>
    <kd value="1.0"/>
  </gazebo>
  <gazebo reference="imu_link">
    <material>Gazebo/Red</material>
  </gazebo>
  <gazebo reference="X_RW">
    <material>Gazebo/DarkGrey</material>
  </gazebo>
  <gazebo reference="Y_RW">
    <material>Gazebo/DarkGrey</material>
  </gazebo>
  <gazebo reference="Z_RW">
    <material>Gazebo/DarkGrey</material>
  </gazebo>
  <gazebo reference="foot">
    <mu1>1.0</mu1>
    <mu2>1.0</mu2>
    <self_collide>1</self_collide>
    <material>Gazebo/DarkGrey</material>
    <kp value="1000000.0"/>
    <kd value="100"/>
    <maxVel>100.0</maxVel>
  </gazebo>
  <!-- <link name="world"/>
    <joint name="base_static_joint" type="fixed">
        <origin rpy="0 0 0" xyz="0 0 0"/>
        <parent link="world"/>
        <child link="base"/>
    </joint> -->
  <link name="base_link">
    <visual>
      <origin rpy="0 0 0" xyz="0 0 0"/>
      <geometry>
        <box size="0.001 0.001 0.001"/>
      </geometry>
    </visual>
  </link>
  <joint name="floating_base" type="fixed">
    <origin rpy="0 0 0" xyz="0 0 0"/>
    <parent link="base_link"/>
    <child link="trunk"/>
  </joint>
  <link name="trunk">
    <visual>
      <origin rpy="0 0 0" xyz="0 0 0"/>
      <geometry>
        <mesh filename="package://example-robot-data/robots/jey_description/meshes/MainBody.stl" scale="1 1 1"/>
      </geometry>
      <material name="orange"/>
    </visual>
    <collision>
      <origin rpy="0 0 0" xyz="0 0 0"/>
      <geometry>
        <mesh filename="package://example-robot-data/robots/jey_description/meshes/MainBody.stl" scale="1 1 1"/>
      </geometry>
    </collision>
    <inertial>
      <origin rpy="0 0 0" xyz="0.0 0.0 -0.01649"/>
      <mass value="0.786592"/>
      <inertia ixx="0.002884" ixy="0.0" ixz="0.0" iyy="0.002884" iyz="0.0" izz="0.001275"/>
    </inertial>
  </link>
  <joint name="imu_joint" type="fixed">
    <parent link="trunk"/>
    <child link="imu_link"/>
    <origin rpy="0 0 0" xyz="0 0 0"/>
  </joint>
  <link name="imu_link">
    <inertial>
      <mass value="0.001"/>
      <origin rpy="0 0 0" xyz="0 0 0"/>
      <inertia ixx="0.0001" ixy="0" ixz="0" iyy="0.0001" iyz="0" izz="0.0001"/>
    </inertial>
    <visual>
      <origin rpy="0 0 0" xyz="0 0 0"/>
      <geometry>
        <box size="0.001 0.001 0.001"/>
      </geometry>
      <material name="red"/>
    </visual>
    <collision>
      <origin rpy="0 0 0" xyz="0 0 0"/>
      <geometry>
        <box size=".001 .001 .001"/>
      </geometry>
    </collision>
  </link>
  <!-- Reactionwheel in the X axis -->
  <joint name="X_RW_joint" type="continuous">
    <origin rpy="0 1.5707963267948966 0" xyz="0.06 0 0"/>
    <parent link="trunk"/>
    <child link="X_RW"/>
    <axis xyz="0 0 1"/>
    <dynamics damping="0" friction="0"/>
    <limit effort="91.0035" velocity="19.69"/>
  </joint>
  <link name="X_RW">
    <visual>
      <origin rpy="0 0 0" xyz="0 0 0"/>
      <geometry>
        <mesh filename="package://example-robot-data/robots/jey_description/meshes/Reactionwheel.stl" scale="1 1 1"/>
      </geometry>
      <material name="silver"/>
    </visual>
    <collision>
      <origin rpy="0 0 0" xyz="0 0 0"/>
      <geometry>
        <mesh filename="package://example-robot-data/robots/jey_description/meshes/Reactionwheel.stl" scale="1 1 1"/>
      </geometry>
    </collision>
    <inertial>
      <origin rpy="0 0 0" xyz="0.0 0.0 0.0"/>
      <mass value="0.047629"/>
      <inertia ixx="4.1892559e-05" ixy="0.0" ixz="0.0" iyy="4.0366712e-05" iyz="0.0" izz="8.213226e-05"/>
    </inertial>
  </link>
  <transmission name="X_RW_tran">
    <type>transmission_interface/SimpleTransmission</type>
    <joint name="X_RW_joint">
      <hardwareInterface>hardware_interface/EffortJointInterface</hardwareInterface>
    </joint>
    <actuator name="X_RW_motor">
      <hardwareInterface>hardware_interface/EffortJointInterface</hardwareInterface>
      <mechanicalReduction>1</mechanicalReduction>
    </actuator>
  </transmission>
  <!-- Reactionwheel in the Y axis -->
  <joint name="Y_RW_joint" type="continuous">
    <origin rpy=" -1.5707963267948966 0 0" xyz="0 0.06 0"/>
    <parent link="trunk"/>
    <child link="Y_RW"/>
    <axis xyz="0 0 1"/>
    <dynamics damping="0" friction="0"/>
    <limit effort="91.0035" velocity="19.69"/>
  </joint>
  <link name="Y_RW">
    <visual>
      <origin rpy="0 0 0" xyz="0 0 0"/>
      <geometry>
        <mesh filename="package://example-robot-data/robots/jey_description/meshes/Reactionwheel.stl" scale="1 1 1"/>
      </geometry>
      <material name="silver"/>
    </visual>
    <collision>
      <origin rpy="0 0 0" xyz="0 0 0"/>
      <geometry>
        <mesh filename="package://example-robot-data/robots/jey_description/meshes/Reactionwheel.stl" scale="1 1 1"/>
      </geometry>
    </collision>
    <inertial>
      <origin rpy="0 0 0" xyz="0.0 0.0 0.0"/>
      <mass value="0.047629"/>
      <inertia ixx="4.1892559e-05" ixy="0.0" ixz="0.0" iyy="4.0366712e-05" iyz="0.0" izz="8.213226e-05"/>
    </inertial>
  </link>
  <transmission name="Y_RW_tran">
    <type>transmission_interface/SimpleTransmission</type>
    <joint name="Y_RW_joint">
      <hardwareInterface>hardware_interface/EffortJointInterface</hardwareInterface>
    </joint>
    <actuator name="Y_RW_motor">
      <hardwareInterface>hardware_interface/EffortJointInterface</hardwareInterface>
      <mechanicalReduction>1</mechanicalReduction>
    </actuator>
  </transmission>
  <!-- Reactionwheel in the Z axis -->
  <joint name="Z_RW_joint" type="continuous">
    <origin rpy="0 0 0" xyz="0 0 0.06"/>
    <parent link="trunk"/>
    <child link="Z_RW"/>
    <axis xyz="0 0 1"/>
    <dynamics damping="0" friction="0"/>
    <limit effort="91.0035" velocity="19.69"/>
  </joint>
  <link name="Z_RW">
    <visual>
      <origin rpy="0 0 0" xyz="0 0 0"/>
      <geometry>
        <mesh filename="package://example-robot-data/robots/jey_description/meshes/Reactionwheel.stl" scale="1 1 1"/>
      </geometry>
      <material name="silver"/>
    </visual>
    <collision>
      <origin rpy="0 0 0" xyz="0 0 0"/>
      <geometry>
        <mesh filename="package://example-robot-data/robots/jey_description/meshes/Reactionwheel.stl" scale="1 1 1"/>
      </geometry>
    </collision>
    <inertial>
      <origin rpy="0 0 0" xyz="0.0 0.0 0.0"/>
      <mass value="0.047629"/>
      <inertia ixx="4.1892559e-05" ixy="0.0" ixz="0.0" iyy="4.0366712e-05" iyz="0.0" izz="8.213226e-05"/>
    </inertial>
  </link>
  <transmission name="Z_RW_tran">
    <type>transmission_interface/SimpleTransmission</type>
    <joint name="Z_RW_joint">
      <hardwareInterface>hardware_interface/EffortJointInterface</hardwareInterface>
    </joint>
    <actuator name="Z_RW_motor">
      <hardwareInterface>hardware_interface/EffortJointInterface</hardwareInterface>
      <mechanicalReduction>1</mechanicalReduction>
    </actuator>
  </transmission>
  <!-- contact point -->
  <joint name="$foot_fixed" type="fixed">
    <origin rpy="0 0 0" xyz="0 0 -0.1"/>
    <parent link="trunk"/>
    <child link="foot"/>
  </joint>
  <link name="foot">
    <visual>
      <origin rpy="0 0 0" xyz="0 0 0"/>
      <geometry>
        <sphere radius="0.0175"/>
      </geometry>
      <material name="green"/>
    </visual>
    <collision>
      <origin rpy="0 0 0" xyz="0 0 0"/>
      <geometry>
        <sphere radius="0.0175"/>
      </geometry>
    </collision>
  </link>
</robot>

